Workbook

Sheet README - Report Guide
B2: Sprint Delivery Report — Report Guide
B3: Read this before using the Master/Pivot tabs. Last reviewed: Aug 2026 (delivery-exec pass).
B5: 1. What this workbook contains
B6: Master sheets | C6: One row per Application/Area. Sprint-level values for Productivity, Velocity, Predictability, Defect Density, and Defects. Same Domain/Workstream/App/Active-App columns are repeated across all five — keep them in sync manually (see Data Quality Flags tab for known drift).
B7: Pivot sheets | C7: Roll-ups by Workstream, one per metric. Converted to static values during this review (see note 5 below) — refresh manually against the Master sheets if source data changes.
B8: Review4 / Review5 | C8: Portfolio-level monthly trend (Oct'25–Jun'26). Two different 'Productivity' figures exist for the same months — see Data Quality Flags tab, item DQ-06, before quoting these numbers.
B9: Productivity Insights / Lead Observations | C9: Narrative summary and per-application owner questions, built off the Pivot Productivity data.
B11: 2. Key metric definitions
B12: Productivity | C12: Velocity ÷ number of contributing FTEs for the period ('SP per member').
B13: Velocity | C13: Total story points accepted in a sprint/period.
B14: Predictability | C14: SP accepted ÷ SP planned for a sprint. Should sit close to 1.0 (100%) if planning is reliable; values far above 1.5x or below 0.5x usually indicate the plan or accept number is being entered inconsistently rather than genuine over/under-delivery.
B15: PRD Defect Density % | C15: Post-production defects (within 23 days of release) ÷ story points delivered.
B16: Q3TD | C16: 'Q3 to date' — a partial quarter (as few as 3 of ~7 sprints). Treat as directional only.
B18: 3. Known limitations (read before presenting this externally)
B19: Partial periods look identical to complete ones | C19: Q3TD averages and Jun'26 in Review4/5 use the same formatting as fully-populated quarters/months. A 'Period Coverage' / 'Coverage Flag' column has been added to Master Productivity and Review4/Review5 in this revision to make this visible at a glance.
B20: Active App flag is not reliable | C20: Two apps are marked Active = No while still carrying live headcount and delivery data (Einstein 360, XM360 Recovery/Reliability). Flagged in yellow on Master Productivity and logged in Data Quality Flags.
B21: Untraceable rows | C21: Master Productivity rows without an SL No / App name but containing sprint values have been highlighted in red with a Data Quality Note. Do not include these in any total until attributed.
B22: Defect logging gaps | C22: The entire Payment & Billing workstream shows 0.000000% defect density across 12 consecutive sprints — more likely an untracked/unlogged metric than a genuine zero-defect result.
B24: 4. Recommended next steps for the report owner
B25: 1. | C25: Decide, and document, one authoritative formula for portfolio 'Productivity' (Review4 column B vs column F disagree by ~8%).
B26: 2. | C26: Standardize the Review4/Review5 divisor logic and document any exception with a stated reason.
B27: 3. | C27: Attribute or delete the unattributed data rows in Master Productivity (highlighted red).
B28: 4. | C28: Reconcile the Active App flag for Einstein 360 and XM360 Recovery/Reliability with actual staffing.
B29: 5. | C29: Confirm whether defect logging is actually wired up for the Payment & Billing workstream.
B30: 6. | C30: Consolidate the five Master sheets onto shared App/Workstream reference data (e.g. via lookup formulas) instead of five independently-maintained copies, to stop the Active-App and naming drift seen above.
B32: 5. What changed in this revision
B33: • | C33: Added this README and the 'Data Quality Flags' tab (consolidated issue log).
B34: • | C34: Master Productivity: added 'Sprints Reported', 'Coverage Flag', and 'Data Quality Note' columns; highlighted 7 unattributed data rows (red) and 2 Active-App inconsistencies (yellow).
B35: • | C35: Review4: labeled the previously-unnamed helper column F and flagged its mismatch with column B; added 'Period Coverage'.
B36: • | C36: Review5: added 'Period Coverage', flagging Jun'26 (partial) and Dec'25 (non-standard divisor).
B37: • | C37: Pivot tables were converted to static values by the recalculation engine used for this review — they no longer auto-refresh from a pivot cache. Rebuild them as live pivots in Excel if that functionality is still needed.

Sheet Data Quality Flags
A1: Data Quality Flags — Consolidated Issue Log
A2: Every row is a specific, verifiable issue found while reviewing this workbook. Resolve or annotate before recirculating.
A4: ID | B4: Sheet(s) | C4: Location | D4: Severity | E4: Issue | F4: Evidence | G4: Recommended action
A5: DQ-01 | B5: Master Productivity | C5: Rows 31-35, 37, 38 (cols L, V) | D5: High | E5: Untraceable sprint data | F5: 7 rows contain live values (Sp17 and Sp1 productivity figures, e.g. 5, 10, 14, 9.07, 8, 6.4) with no SL No, Domain, Workstream, or Application/Area attached. | G5: Attribute to the correct application or delete before this report is recirculated. Do not include in any total until resolved.
A6: DQ-02 | B6: Master Productivity / Master Data Velocity | C6: Row 10 (XM360 Recovery/Reliability), Row 22 (Einstein 360) | D6: High | E6: Active App = 'No' but app is fully staffed and delivering | F6: XM360 Recovery/Reliability shows 6.5 Developer/QA in Q3/Q4 with ongoing sprint velocity; Einstein 360 shows 4.0 FTE with continuous Sp16-26 delivery data. Both flagged 'Active App: No'. | G6: Confirm with the app owners whether the Active flag or the delivery data is stale, and correct one of them.
A7: DQ-03 | B7: Master Data Predictability | C7: Flow Engine (optimus) row; CPOS row | D7: High | E7: Predictability ratio is not a believable signal | F7: Flow Engine (optimus), a 2-person team, shows sprint predictability of 12.0x, 5.67x (x3), 5.33x, 4.43x, 4.4x, 3.57x, 3.33x, 3.25x, 2.16x, 2.0x planned capacity. CPOS swings between 0.28x and 4.67x. | G7: Audit how 'SP planned' is captured for these two teams — a metric this volatile is more likely a data-entry issue than genuine delivery variance.
A8: DQ-04 | B8: Master Defects | C8: XM360 CBM/Phoenix, Sp 6 column | D8: Medium | E8: Defect count outlier | F8: 81 defects logged in Sp6 vs 5, 7, 9, 24, 28 in the surrounding sprints for the same app — roughly 3x the next-highest sprint for this app. | G8: Verify this is a real quality incident (and capture root cause) rather than a data entry error, since it did not move PRD Defect Density that sprint.
A9: DQ-05 | B9: Pivot PRD Defect Density | C9: Payment & Billing rows, Q1 and Q2 columns | D9: Medium | E9: Suspiciously clean defect data | F9: All four Payment & Billing scrums (XRM - VOIXM/Video/HSD, DevOps) report exactly 0.000000% defect density across 12 consecutive sprints. | G9: Confirm defects are actually being logged against this workstream's apps, rather than tracked in a separate system that doesn't feed this report.
A10: DQ-06 | B10: Review4 | C10: Column B vs Column F | D10: High | E10: Two disagreeing 'Productivity' figures for the same months | F10: Column B is a hardcoded value (no formula). Column F (labeled here for the first time) is a live formula '=Velocity/FTE contributing/divisor'. For Oct'25 they read 7.22 vs 6.67 — an 8% gap — and every other month disagrees similarly. | G10: Pick one authoritative definition and make column B a live formula referencing it, so the two can never drift again.
A11: DQ-07 | B11: Review4 / Review5 | C11: Row 10 (Jun'26) | D11: Medium | E11: Partial month presented like a complete one | F11: Jun'26 uses a productivity divisor of 1 vs 2 for every other month, because it is a half-reported period. Velocity (868) looks like a cliff next to May'26 (1,785) purely because of this. | G11: Label partial months explicitly wherever this trend is charted (now done via the new 'Period Coverage' column) so viewers don't read it as a real decline.
A12: DQ-08 | B12: Review5 | C12: Row 4 (Dec'25) | D12: Low | E12: Undocumented divisor exception | F12: Dec'25 uses a productivity divisor of 3, the only month that isn't 1 or 2, with no note explaining why. | G12: Add a one-line reason (e.g. extra pay period / 3-sprint month) so the exception doesn't look like an error.
A13: DQ-09 | B13: Master Productivity | C13: App-level, e.g. CPOS | D13: Medium | E13: Quarterly averages built from very sparse sprint data | F13: CPOS has real values in only 3 of 15 tracked sprints (Sp12-26), yet its quarterly averages are displayed with the same formatting/confidence as fully-populated apps. | G13: Use the new 'Sprints Reported' / 'Coverage Flag' columns added to this sheet to caveat any app below ~50% coverage in commentary.
A14: DQ-10 | B14: All five Master sheets | C14: Domain/Workstream/App/Active-App columns | D14: Medium | E14: Same reference data duplicated across 5 sheets | F14: Productivity, Velocity, Predictability, Defect Density, and Defects each maintain their own copy of Domain/Workstream/Application/Active-App. DQ-02 shows these have already drifted. | G14: Long-term: maintain one reference table (App × Domain × Workstream × Active flag) and have each Master sheet look it up, instead of five independently hand-maintained copies.

Sheet Master Productivity
A1: SL No | B1: Domain | C1: Workstream | D1: QBR | E1: Application/Area | F1: Active App | G1: Sp 12 Scrum Productivity in SP (Velocity by member) | H1: Sp 13 Scrum Productivity in SP (Velocity by member) | I1: Sp 14 Scrum Productivity in SP (Velocity by member) | J1: Sp 15 Scrum Productivity in SP (Velocity by member) | K1: Sp 16 Scrum Productivity in SP (Velocity by member) | L1: Sp 17 Scrum Productivity in SP (Velocity by member) | M1: Sp 18 Scrum Productivity in SP (Velocity by member) | N1: Sp 19 Scrum Productivity in SP (Velocity by member) | O1: Sp 20 Scrum Productivity in SP (Velocity by member) | P1: Sp 21 Scrum Productivity in SP (Velocity by member) | Q1: Sp 22 Scrum Productivity in SP (Velocity by member) | R1: Sp 23 Scrum Productivity in SP (Velocity by member) | S1: Sp 24 Scrum Productivity in SP (Velocity by member) | T1: Sp 25 Scrum Productivity in SP (Velocity by member) | U1: Sp 26 Scrum Productivity in SP (Velocity by member) | V1: Avg of 15 SP (From 12 to 26) | W1: Avg Of Q3 Sprints(SP 14 to 19) | X1: Avg Of Q4 Sprints(SP 20 to 26) | Y1: Sp 1 Scrum Productivity in SP (Velocity by member) | Z1: Sp 2 Scrum Productivity in SP (Velocity by member) | AA1: Sp 3 Scrum Productivity in SP (Velocity by member) | AB1: Sp 4 Scrum Productivity in SP (Velocity by member) | AC1: Sp 5 Scrum Productivity in SP (Velocity by member) | AD1: Sp 6 Scrum Productivity in SP (Velocity by member) | AE1: Avg Of Q1 Sprints(SP 1 to 6) | AF1: Sp 7 Scrum Productivity in SP (Velocity by member) | AG1: Sp 8 Scrum Productivity in SP (Velocity by member) | AH1: Sp 9 Scrum Productivity in SP (Velocity by member) | AI1: Sp 10 Scrum Productivity in SP (Velocity by member) | AJ1: Sp 11 Scrum Productivity in SP (Velocity by member) | AK1: Sp 12 Scrum Productivity in SP (Velocity by member) | AL1: Avg Of Q2 Sprints(SP 7 to 12) | AM1: Sp 13 Scrum Productivity in SP (Velocity by member) | AN1: Sp 14 Scrum Productivity in SP (Velocity by member) | AO1: Sp 15 Scrum Productivity in SP (Velocity by member) | AP1: Sp 16 Scrum Productivity in SP (Velocity by member) | AQ1: Sp 17 Scrum Productivity in SP (Velocity by member) | AR1: Sp 18 Scrum Productivity in SP (Velocity by member) | AS1: Sp 19 Scrum Productivity in SP (Velocity by member) | AT1: Avg Of Q3 Sprints(SP 13 to 15) | AU1: Sprints Reported (Sp12-26, of 15) | AV1: Coverage Flag | AW1: Data Quality Note
A2: 1 | B2: IXT | C2: CEUI | D2: Assisted Tools | E2: CPOS | F2: Yes | S2: 4.6666667 | T2: 3.6666667 | U2: 6.5 | V2: =AVERAGE(G2:U2) -> 4.9444444 | X2: =AVERAGE(O2:U2) -> 4.9444444 | Y2: 3.25 | Z2: 6.75 | AA2: 8.25 | AB2: 5.5 | AC2: 3 | AD2: 10.5 | AE2: =AVERAGE(Y2:AD2) -> 6.2083333 | AF2: 7.25 | AG2: 5.75 | AH2: 5.6 | AI2: 5.2 | AJ2: 6.75 | AK2: 8 | AL2: =AVERAGE(AF2:AK2) -> 6.425 | AM2: 8 | AN2: 7.25 | AO2: 0 | AT2: =AVERAGE(AM2:AR2) -> 5.0833333 | AU2: =COUNT(G2:U2) -> 3 | AV2: =IF(AU2<5,"Low coverage",IF(AU2<15,"Partial","Full")) -> Low coverage
A3: 2 | B3: IXT | C3: CEUI | D3: Assisted Tools | E3: Xumo | F3: Yes | G3: 9.5714286 | H3: 10.571429 | I3: 12 | J3: 8.8 | K3: 8.9090909 | L3: 9.8181818 | M3: 9 | N3: 9.3333333 | O3: 9.0769231 | P3: 8.1538462 | Q3: 8 | R3: 10.307692 | S3: 10.62 | T3: 8.46 | U3: 3.7 | V3: =AVERAGE(G3:U3) -> 9.0881283 | W3: =AVERAGE(I3:N3) -> 9.6434343 | X3: =AVERAGE(O3:U3) -> 8.3312088 | Y3: 7.82 | Z3: 7.27 | AA3: 9.2 | AB3: 10.4 | AC3: 9.8 | AD3: 9.4 | AE3: =AVERAGE(Y3:AD3) -> 8.9816667 | AF3: 10 | AG3: 10.6 | AH3: 10.6 | AI3: 10.4 | AJ3: 10.6 | AK3: 11.8 | AL3: =AVERAGE(AF3:AK3) -> 10.666667 | AM3: 10.8 | AN3: 13.8 | AO3: 10.2 | AT3: =AVERAGE(AM3:AR3) -> 11.6 | AU3: =COUNT(G3:U3) -> 15 | AV3: =IF(AU3<5,"Low coverage",IF(AU3<15,"Partial","Full")) -> Full
A4: 3 | B4: IXT | C4: CEUI | D4: Platform | E4: Flow Engine (prometheus) | F4: Yes | G4: 3.1111111 | H4: 3.5555556 | I4: 2.2222222 | J4: 2.8888889 | K4: 3.3333333 | L4: 3 | M4: 2.4 | N4: 4.3 | O4: 3.9 | P4: 5 | Q4: 4 | R4: 3.5555556 | S4: 4.06 | T4: 3.94 | U4: 5.1111111 | V4: =AVERAGE(G4:U4) -> 3.6251852 | W4: =AVERAGE(I4:N4) -> 3.0240741 | X4: =AVERAGE(O4:U4) -> 4.2238095 | Y4: 3 | Z4: 4.33 | AA4: 4 | AB4: 4.33 | AC4: 4.22 | AD4: 3.56 | AE4: =AVERAGE(Y4:AD4) -> 3.9066667 | AF4: 4.1111111 | AG4: 3.7777778 | AH4: 4.11 | AI4: 4.8888889 | AJ4: 5.33 | AK4: 5.3888889 | AL4: =AVERAGE(AF4:AK4) -> 4.6011111 | AM4: 5 | AN4: 5.56 | AO4: 5.6666667 | AT4: =AVERAGE(AM4:AR4) -> 5.4088889 | AU4: =COUNT(G4:U4) -> 15 | AV4: =IF(AU4<5,"Low coverage",IF(AU4<15,"Partial","Full")) -> Full
A5: 4 | B5: IXT | C5: CEUI | D5: Platform | E5: Flow Engine (optimus) | F5: Yes | G5: 4.25 | H5: 4 | I5: 5.25 | J5: 5 | K5: 4.25 | L5: 4 | M5: 3.25 | N5: 4.75 | O5: 4.3 | P5: 4 | Q5: 3.5 | R5: 5 | S5: 4.5 | T5: 4.25 | U5: 4 | V5: =AVERAGE(G5:U5) -> 4.2866667 | W5: =AVERAGE(I5:N5) -> 4.4166667 | X5: =AVERAGE(O5:U5) -> 4.2214286 | Y5: 3.25 | Z5: 4.25 | AA5: 4.75 | AB5: 5 | AC5: 6 | AD5: 3.25 | AE5: =AVERAGE(Y5:AD5) -> 4.4166667 | AF5: 4.25 | AG5: 4 | AH5: 4.5 | AI5: 5 | AJ5: 4 | AK5: 4 | AL5: =AVERAGE(AF5:AK5) -> 4.2916667 | AM5: 3.25 | AN5: 5 | AO5: 5.25 | AT5: =AVERAGE(AM5:AR5) -> 4.5 | AU5: =COUNT(G5:U5) -> 15 | AV5: =IF(AU5<5,"Low coverage",IF(AU5<15,"Partial","Full")) -> Full
A6: 5 | B6: IXT | C6: CEUI | D6: Platform | E6: Celestial (Titan) | F6: Yes | G6: 7.8333333 | H6: 7.1666667 | I6: 10 | J6: 12.5 | K6: 13.333333 | L6: 7.8333333 | M6: 13.666667 | N6: 11.166667 | O6: 11.2 | P6: 11.4 | Q6: 10.8 | R6: 10 | S6: 12 | T6: 11 | U6: 7.2 | V6: =AVERAGE(G6:U6) -> 10.473333 | W6: =AVERAGE(I6:N6) -> 11.416667 | X6: =AVERAGE(O6:U6) -> 10.514286 | Y6: 11.4 | Z6: 13 | AA6: 12.6 | AB6: 12 | AC6: 12.4 | AD6: 9.5714286 | AE6: =AVERAGE(Y6:AD6) -> 11.828571 | AF6: 12.8 | AG6: 14.2 | AH6: 13.2 | AI6: 14 | AJ6: 12 | AK6: 12 | AL6: =AVERAGE(AF6:AK6) -> 13.033333 | AM6: 13.2 | AN6: 14 | AO6: 15 | AT6: =AVERAGE(AM6:AR6) -> 14.066667 | AU6: =COUNT(G6:U6) -> 15 | AV6: =IF(AU6<5,"Low coverage",IF(AU6<15,"Partial","Full")) -> Full
A7: 6 | B7: IXT | C7: CEUI | D7: Platform | E7: Celestial (Universal) | F7: Yes | G7: 7.6363636 | H7: 6.9090909 | I7: 7.3333333 | J7: 8.5 | K7: 8.1666667 | L7: 8 | M7: 5.8333333 | N7: 8.3333333 | O7: 8.2857143 | P7: 7.9 | Q7: 8.2857143 | R7: 7.1428571 | S7: 7.43 | T7: 7.57 | U7: 9.3 | V7: =AVERAGE(G7:U7) -> 7.7750938 | W7: =AVERAGE(I7:N7) -> 7.6944444 | X7: =AVERAGE(O7:U7) -> 7.9877551 | Y7: 9 | Z7: 8.28 | AA7: 9.14 | AB7: 9.71 | AC7: 8.86 | AD7: 8.25 | AE7: =AVERAGE(Y7:AD7) -> 8.8733333 | AF7: 9 | AG7: 9.2857143 | AH7: 9.14 | AI7: 9.5714286 | AJ7: 10.14 | AK7: 9.5714286 | AL7: =AVERAGE(AF7:AK7) -> 9.4514286 | AM7: 10.57 | AN7: 9.86 | AO7: 10.142857 | AT7: =AVERAGE(AM7:AR7) -> 10.190952 | AU7: =COUNT(G7:U7) -> 15 | AV7: =IF(AU7<5,"Low coverage",IF(AU7<15,"Partial","Full")) -> Full
A8: 7 | B8: IXT | C8: CEUI | D8: Platform | E8: Right Answers | F8: Yes | G8: 8.5 | H8: 9 | I8: 7.5 | J8: 8.5 | K8: 9 | L8: 9 | M8: 8.5 | N8: 13 | O8: 9 | P8: 7.5 | Q8: 6.5 | R8: 3.5 | S8: 6.5 | T8: 4 | U8: 6 | V8: =AVERAGE(G8:U8) -> 7.7333333 | W8: =AVERAGE(I8:N8) -> 9.25 | X8: =AVERAGE(O8:U8) -> 6.1428571 | Y8: 3 | Z8: 4.5 | AA8: 2 | AB8: 2 | AC8: 7.33 | AD8: 6.6666667 | AE8: =AVERAGE(Y8:AD8) -> 4.2494444 | AF8: 11.5 | AG8: 12.5 | AH8: 5.5 | AI8: 10.5 | AJ8: 9.5 | AK8: 10.5 | AL8: =AVERAGE(AF8:AK8) -> 10 | AM8: 11 | AN8: 9 | AO8: 10 | AT8: =AVERAGE(AM8:AR8) -> 10 | AU8: =COUNT(G8:U8) -> 15 | AV8: =IF(AU8<5,"Low coverage",IF(AU8<15,"Partial","Full")) -> Full
A9: 8 | B9: IXT | C9: CEUI | D9: Assisted Tools | E9: XM360 CBM/Phoenix | F9: Yes | G9: 4.5 | H9: 5 | I9: 3 | J9: 9 | K9: 3.4285714 | L9: 7.8571429 | M9: 5 | N9: 8.1428571 | O9: 8.375 | P9: 8.25 | Q9: 7.875 | R9: 9.75 | S9: 7.5 | T9: 4.87 | U9: 5.125 | V9: =AVERAGE(G9:U9) -> 6.5115714 | W9: =AVERAGE(I9:N9) -> 6.0714286 | X9: =AVERAGE(O9:U9) -> 7.3921429 | Y9: 3.75 | Z9: 7.25 | AA9: 8.5 | AB9: 10.12 | AC9: 7.38 | AD9: 7.625 | AE9: =AVERAGE(Y9:AD9) -> 7.4375 | AF9: 7.25 | AG9: 5.125 | AH9: 6.38 | AI9: 5.125 | AJ9: 4.88 | AK9: 6.125 | AL9: =AVERAGE(AF9:AK9) -> 5.8141667 | AM9: 5.13 | AN9: 5.88 | AO9: 4.875 | AT9: =AVERAGE(AM9:AR9) -> 5.295 | AU9: =COUNT(G9:U9) -> 15 | AV9: =IF(AU9<5,"Low coverage",IF(AU9<15,"Partial","Full")) -> Full
A10: 9 | B10: IXT | C10: CEUI | D10: Assisted Tools | E10: XM360 Recovery/Reliability | F10: No | G10: 7.8571429 | H10: 7.1428571 | I10: 6.375 | J10: 5.375 | K10: 5.625 | L10: 5.5 | M10: 4.3076923 | N10: 5.8461538 | O10: 6.9230769 | P10: 8 | Q10: 9.0769231 | R10: 8.4615385 | S10: 7.85 | T10: 7.69 | U10: 6.9230769 | V10: =AVERAGE(G10:U10) -> 6.8635641 | W10: =AVERAGE(I10:N10) -> 5.5048077 | X10: =AVERAGE(O10:U10) -> 7.8463736 | AU10: =COUNT(G10:U10) -> 15 | AV10: =IF(AU10<5,"Low coverage",IF(AU10<15,"Partial","Full")) -> Full | AW10: Active App = No, but this app carries live headcount and delivery data elsewhere in the workbook (see Data Quality Flags tab). Confirm whether the Active App flag or the delivery data is correct.
A11: 10 | B11: IXT | C11: CEUI | D11: Assisted Tools | E11: XM360 Supersonix | F11: Yes | G11: 3.6 | H11: 5.2 | I11: 7.7333333 | J11: 5.7333333 | K11: 6 | L11: 6.2666667 | M11: 6.2222222 | N11: 4.8888889 | O11: 6.2222222 | P11: 7.1111111 | Q11: 8.6666667 | R11: 10.444444 | S11: 7.33 | T11: 6 | U11: 6.4444444 | V11: =AVERAGE(G11:U11) -> 6.5242222 | W11: =AVERAGE(I11:N11) -> 6.1407407 | X11: =AVERAGE(O11:U11) -> 7.4598412 | Y11: 3.38 | Z11: 7.75 | AA11: 8.25 | AB11: 7.12 | AC11: 9.88 | AD11: 9.375 | AE11: =AVERAGE(Y11:AD11) -> 7.6258333 | AF11: 7.375 | AG11: 8.25 | AH11: 8.75 | AI11: 9.375 | AJ11: 6.38 | AK11: 4.75 | AL11: =AVERAGE(AF11:AK11) -> 7.48 | AM11: 5.25 | AN11: 5.38 | AO11: 5.5 | AT11: =AVERAGE(AM11:AR11) -> 5.3766667 | AU11: =COUNT(G11:U11) -> 15 | AV11: =IF(AU11<5,"Low coverage",IF(AU11<15,"Partial","Full")) -> Full
A12: 11 | B12: IXT | C12: CEUI | D12: Assisted Tools | E12: XM Velocity 1/Xceeders | F12: Yes | G12: 1.6923077 | H12: 6.3076923 | I12: 3.0769231 | J12: 2.4615385 | K12: 6.4615385 | L12: 3.3846154 | M12: 4.4615385 | N12: 5.5384615 | O12: 7.0769231 | P12: 6.3076923 | Q12: 3.0769231 | R12: 7.0769231 | S12: 5.69 | T12: 6.5 | U12: 4 | V12: =AVERAGE(G12:U12) -> 4.8742051 | W12: =AVERAGE(I12:N12) -> 4.2307692 | X12: =AVERAGE(O12:U12) -> 5.6754945 | Y12: 6.92 | Z12: 7.5 | AA12: 6.29 | AB12: 7.85 | AC12: 6.31 | AD12: 7.2307692 | AE12: =AVERAGE(Y12:AD12) -> 7.0167949 | AF12: 5.8461538 | AG12: 5.8461538 | AH12: 5.69 | AI12: 9.08 | AJ12: 8.17 | AK12: 9 | AL12: =AVERAGE(AF12:AK12) -> 7.2720513 | AM12: 5.82 | AN12: 9 | AO12: 8.73 | AT12: =AVERAGE(AM12:AR12) -> 7.85 | AU12: =COUNT(G12:U12) -> 15 | AV12: =IF(AU12<5,"Low coverage",IF(AU12<15,"Partial","Full")) -> Full
A13: 12 | B13: IXT | C13: CEUI | D13: Assisted Tools | E13: XM Velocity 2/Xplorers | F13: Yes | G13: 3.6923077 | H13: 10.307692 | I13: 5.3333333 | J13: 1.8666667 | K13: 3.3333333 | L13: 3.3333333 | M13: 4.2666667 | N13: 4.6666667 | O13: 5.2 | P13: 2.8 | Q13: 3.8666667 | R13: 5.0666667 | S13: 4.26 | T13: 4.5 | U13: 3.8666667 | V13: =AVERAGE(G13:U13) -> 4.424 | W13: =AVERAGE(I13:N13) -> 3.8 | X13: =AVERAGE(O13:U13) -> 4.2228571 | Y13: 6.13 | Z13: 4.9 | AA13: 6 | AB13: 7.83 | AC13: 4.33 | AD13: 7.8333333 | AE13: =AVERAGE(Y13:AD13) -> 6.1705556 | AF13: 6.8333333 | AG13: 6.0833333 | AH13: 4.46 | AI13: 7.8461538 | AJ13: 7.8571429 | AK13: 6.5714286 | AL13: =AVERAGE(AF13:AK13) -> 6.6085653 | AU13: =COUNT(G13:U13) -> 15 | AV13: =IF(AU13<5,"Low coverage",IF(AU13<15,"Partial","Full")) -> Full
A14: 13 | B14: IXT | C14: Field experience | D14: Field Experience | E14: NWT - UI | F14: Yes | G14: 9.5348837 | H14: 6.744186 | I14: 8.1176471 | J14: 7.8 | K14: 8.9 | L14: 8.3 | M14: 8.2 | N14: 10.8 | O14: 5.9 | P14: 9.1 | Q14: 6.6 | R14: 7.4117 | S14: 8 | T14: 6.9 | U14: 6.3529412 | V14: =AVERAGE(G14:U14) -> 7.9107572 | W14: =AVERAGE(I14:N14) -> 8.6862745 | X14: =AVERAGE(O14:U14) -> 7.180663 | Y14: 7.41 | Z14: 5.1 | AA14: 11.1 | AB14: 9.7 | AC14: 7.29 | AD14: 6 | AE14: =AVERAGE(Y14:AD14) -> 7.7666667 | AF14: 7.8 | AG14: 9.6 | AH14: 7.4 | AI14: 13.4 | AJ14: 5 | AK14: 7.3333333 | AL14: =AVERAGE(AF14:AK14) -> 8.4222222 | AM14: 5.83 | AN14: 8.5 | AO14: 10 | AT14: =AVERAGE(AM14:AR14) -> 8.11 | AU14: =COUNT(G14:U14) -> 15 | AV14: =IF(AU14<5,"Low coverage",IF(AU14<15,"Partial","Full")) -> Full
A15: 14 | B15: IXT | C15: Field experience | D15: Field Experience | E15: NWT-FSM | F15: Yes | J15: 6.6 | K15: 4.9 | L15: 5.7 | M15: 4 | N15: 5.7 | O15: 7.7 | P15: 5.7 | Q15: 2.9 | R15: 4.5714 | S15: 6 | T15: 3.3 | U15: 8 | V15: =AVERAGE(G15:U15) -> 5.4226167 | W15: =AVERAGE(I15:N15) -> 5.38 | X15: =AVERAGE(O15:U15) -> 5.4530571 | Y15: 2 | Z15: 5.3 | AA15: 5.3 | AB15: 7 | AC15: 6.29 | AD15: 4.8571429 | AE15: =AVERAGE(Y15:AD15) -> 5.1245238 | AF15: 9.2 | AG15: 8.4 | AH15: 5.33 | AI15: 8 | AJ15: 6.8 | AK15: 10.8 | AL15: =AVERAGE(AF15:AK15) -> 8.0883333 | AM15: 10 | AN15: 8.7 | AO15: 8.4 | AT15: =AVERAGE(AM15:AR15) -> 9.0333333 | AU15: =COUNT(G15:U15) -> 12 | AV15: =IF(AU15<5,"Low coverage",IF(AU15<15,"Partial","Full")) -> Partial
A16: 15 | B16: IXT | C16: Field experience | D16: Field Experience | E16: NWT - PSNB | F16: Yes | G16: 9.4444444 | H16: 11.944444 | I16: 7.75 | J16: 9.5 | K16: 8.5 | L16: 8.25 | M16: 7 | N16: 9.5 | O16: 7 | P16: 10.75 | Q16: 7.8 | R16: 9 | S16: 13.65 | T16: 9 | U16: 3.75 | V16: =AVERAGE(G16:U16) -> 8.8559259 | W16: =AVERAGE(I16:N16) -> 8.4166667 | X16: =AVERAGE(O16:U16) -> 8.7071429 | Y16: 10 | Z16: 7 | AA16: 8.8 | AB16: 5.8 | AC16: 8.25 | AD16: 4.5 | AE16: =AVERAGE(Y16:AD16) -> 7.3916667 | AF16: 8.5 | AG16: 6 | AH16: 5.5 | AI16: 4.5 | AJ16: 5.5 | AK16: 5.25 | AL16: =AVERAGE(AF16:AK16) -> 5.875 | AM16: 5.5 | AT16: =AVERAGE(AM16:AR16) -> 5.5 | AU16: =COUNT(G16:U16) -> 15 | AV16: =IF(AU16<5,"Low coverage",IF(AU16<15,"Partial","Full")) -> Full
A17: 16 | B17: IXT | C17: Field experience | D17: Field Experience | E17: NWT - Core | F17: Yes | G17: 9.3 | H17: 8.8 | I17: 8.5 | J17: 9.1 | K17: 9.2 | L17: 7.9 | M17: 7.8 | N17: 8.8 | O17: 6.2 | P17: 7.2 | Q17: 9.1 | R17: 8.8 | S17: 9 | T17: 8.9 | U17: 7.6 | V17: =AVERAGE(G17:U17) -> 8.4133333 | W17: =AVERAGE(I17:N17) -> 8.55 | X17: =AVERAGE(O17:U17) -> 8.1142857 | Y17: 6.6 | Z17: 7.9 | AA17: 8.8 | AB17: 8.8 | AC17: 8.2 | AE17: =AVERAGE(Y17:AD17) -> 8.06 | AF17: 0.89 | AG17: 6.2 | AH17: 5.8 | AI17: - | AL17: =AVERAGE(AF17:AK17) -> 4.2966667 | AU17: =COUNT(G17:U17) -> 15 | AV17: =IF(AU17<5,"Low coverage",IF(AU17<15,"Partial","Full")) -> Full
A18: 17 | B18: IXT | C18: Payment & Billing | D18: XRM | E18: XRM - VOIXM Scrum | F18: Yes | G18: 5.3333333 | H18: 4 | I18: 2.6363636 | J18: 3.8181818 | K18: 4.7272727 | L18: 5.1818182 | M18: 3.9 | N18: 5 | O18: 5.2 | P18: 5.5 | Q18: 5.4 | R18: 5.2 | S18: 5.9 | T18: 5.9 | U18: 5.4 | V18: =AVERAGE(G18:U18) -> 4.8731313 | W18: =AVERAGE(I18:N18) -> 4.2106061 | X18: =AVERAGE(O18:U18) -> 5.5 | Y18: 4.9 | Z18: 5.6 | AA18: 5.36 | AB18: 6.81 | AC18: 6 | AD18: 6.5454545 | AE18: =AVERAGE(Y18:AD18) -> 5.8692424 | AF18: 6.4 | AG18: 6.7 | AH18: 5.8 | AI18: 5.9 | AJ18: 5.2 | AK18: 5.2 | AL18: =AVERAGE(AF18:AK18) -> 5.8666667 | AM18: 5.3 | AN18: 6 | AO18: 5.4 | AT18: =AVERAGE(AM18:AR18) -> 5.5666667 | AU18: =COUNT(G18:U18) -> 15 | AV18: =IF(AU18<5,"Low coverage",IF(AU18<15,"Partial","Full")) -> Full
A19: 18 | B19: IXT | C19: Payment & Billing | D19: XRM | E19: XRM - Video Scrum | F19: Yes | G19: 4.9 | H19: 7.3 | I19: 6.2727273 | J19: 6.9090909 | K19: 7.5454545 | L19: 6.3636364 | M19: 5.7272727 | N19: 6.7272727 | O19: 6 | P19: 6.9 | Q19: 6.5 | R19: 6.4 | S19: 6.1 | T19: 6.1 | U19: 4.7272727 | V19: =AVERAGE(G19:U19) -> 6.2981818 | W19: =AVERAGE(I19:N19) -> 6.5909091 | X19: =AVERAGE(O19:U19) -> 6.1038961 | Y19: 5.9 | Z19: 5.6 | AA19: 7.45 | AB19: 7.18 | AC19: 6.45 | AD19: 5.9090909 | AE19: =AVERAGE(Y19:AD19) -> 6.4148485 | AF19: 6.8 | AG19: 6.1 | AH19: 5.27 | AI19: 6.2727273 | AJ19: 7.0909091 | AK19: 6.8181818 | AL19: =AVERAGE(AF19:AK19) -> 6.3919697 | AM19: 7.09 | AN19: 7 | AO19: 7.0909091 | AT19: =AVERAGE(AM19:AR19) -> 7.060303 | AU19: =COUNT(G19:U19) -> 15 | AV19: =IF(AU19<5,"Low coverage",IF(AU19<15,"Partial","Full")) -> Full
A20: 19 | B20: IXT | C20: Payment & Billing | D20: XRM | E20: XRM - HSD Scrum | F20: Yes | G20: 4.4444444 | H20: 5.4444444 | I20: 4.6 | J20: 4.9 | K20: 4.7 | L20: 5.3 | M20: 5.5 | N20: 5.4 | O20: 4.3 | P20: 6.3 | Q20: 5.9 | R20: 4.5 | S20: 2.2 | T20: 5 | U20: 3.43 | V20: =AVERAGE(G20:U20) -> 4.7945926 | W20: =AVERAGE(I20:N20) -> 5.0666667 | X20: =AVERAGE(O20:U20) -> 4.5185714 | Y20: 3 | Z20: 4.5 | AA20: 4.82 | AB20: 5.36 | AC20: 6.58 | AD20: 5.0833333 | AE20: =AVERAGE(Y20:AD20) -> 4.8905556 | AF20: 5.3636364 | AG20: 5.2818182 | AH20: 5.7 | AI20: 5.2 | AJ20: 4.5 | AK20: 8 | AL20: =AVERAGE(AF20:AK20) -> 5.6742424 | AM20: 3.6 | AN20: 4.8 | AO20: 5.5 | AT20: =AVERAGE(AM20:AR20) -> 4.6333333 | AU20: =COUNT(G20:U20) -> 15 | AV20: =IF(AU20<5,"Low coverage",IF(AU20<15,"Partial","Full")) -> Full
A21: 20 | B21: IXT | C21: Payment & Billing | D21: BXT | E21: DevOps | F21: Yes | G21: 7.1 | H21: 5.4 | I21: 6.2222222 | J21: 6.3333333 | K21: 5.4444444 | L21: 4.6666667 | M21: 6.7777778 | N21: 6.1111111 | O21: 6.1111111 | P21: 3.5555556 | Q21: 5.11 | R21: 6 | S21: 5.77 | T21: 3.88 | U21: 3.3333333 | V21: =AVERAGE(G21:U21) -> 5.4543704 | W21: =AVERAGE(I21:N21) -> 5.9259259 | X21: =AVERAGE(O21:U21) -> 4.8228571 | Y21: 6.22 | Z21: 6.11 | AA21: 6.11 | AB21: 6.33 | AC21: 6.44 | AD21: 6.5 | AE21: =AVERAGE(Y21:AD21) -> 6.285 | AF21: 5.4444444 | AG21: 6.6666667 | AH21: 6.22 | AI21: 7 | AJ21: 7.22 | AK21: 8.2222222 | AL21: =AVERAGE(AF21:AK21) -> 6.7955556 | AM21: 9.56 | AN21: 8.78 | AT21: =AVERAGE(AM21:AR21) -> 9.17 | AU21: =COUNT(G21:U21) -> 15 | AV21: =IF(AU21<5,"Low coverage",IF(AU21<15,"Partial","Full")) -> Full
A22: 21 | B22: IXT | C22: CEUI | D22: Assisted Tools | E22: Einstein 360 | F22: No | K22: 1.25 | L22: 8 | M22: 5.5 | N22: 5.5 | O22: 8 | P22: 5.5 | Q22: 5.75 | R22: 5.25 | S22: 6.75 | T22: 3.25 | U22: 5.5 | V22: =AVERAGE(G22:U22) -> 5.4772727 | W22: =AVERAGE(I22:N22) -> 5.0625 | X22: =AVERAGE(O22:U22) -> 5.7142857 | AU22: =COUNT(G22:U22) -> 11 | AV22: =IF(AU22<5,"Low coverage",IF(AU22<15,"Partial","Full")) -> Partial | AW22: Active App = No, but this app carries live headcount and delivery data elsewhere in the workbook (see Data Quality Flags tab). Confirm whether the Active App flag or the delivery data is correct.
A23: 22 | B23: IXT | C23: Payment & Billing | D23: Account Services | E23: Account Services - BRE | F23: Yes | O23: 16 | P23: 13 | Q23: 13 | R23: 14.5 | S23: 9 | T23: 7.5 | U23: 12 | V23: =AVERAGE(G23:U23) -> 12.142857 | W23: =AVERAGE(I23:U23) -> 12.142857 | X23: =AVERAGE(O23:U23) -> 12.142857 | Y23: 12 | Z23: 11.5 | AA23: 14 | AB23: 11.5 | AC23: 12 | AD23: 9 | AE23: =AVERAGE(Y23:AD23) -> 11.666667 | AF23: 13 | AG23: 14 | AH23: 14 | AI23: 15 | AJ23: 12.5 | AK23: 13.5 | AL23: =AVERAGE(AF23:AK23) -> 13.666667 | AM23: 10.5 | AN23: 12 | AO23: 12 | AT23: =AVERAGE(AM23:AR23) -> 11.5 | AU23: =COUNT(G23:U23) -> 7 | AV23: =IF(AU23<5,"Low coverage",IF(AU23<15,"Partial","Full")) -> Partial
A24: 23 | B24: IXT | C24: Payment & Billing | D24: Account Services | E24: Account Services - XM PDF | F24: Yes | O24: 10 | P24: 8.25 | Q24: 12.75 | R24: 12.75 | S24: 10.25 | T24: 6 | U24: 2.25 | V24: =AVERAGE(G24:U24) -> 8.8928571 | W24: =AVERAGE(I24:U24) -> 8.8928571 | X24: =AVERAGE(O24:U24) -> 8.8928571 | Y24: 14 | Z24: 14 | AA24: 12.67 | AB24: 11.33 | AC24: 8.75 | AD24: 9.6666667 | AE24: =AVERAGE(Y24:AD24) -> 11.736111 | AF24: 6 | AG24: 12 | AH24: 11.75 | AI24: 11.5 | AJ24: 10 | AK24: 9.8 | AL24: =AVERAGE(AF24:AK24) -> 10.175 | AM24: 8.6 | AN24: 10 | AO24: 9.2 | AT24: =AVERAGE(AM24:AR24) -> 9.2666667 | AU24: =COUNT(G24:U24) -> 7 | AV24: =IF(AU24<5,"Low coverage",IF(AU24<15,"Partial","Full")) -> Partial
A25: 24 | B25: IXT | C25: Payment & Billing | D25: Account Services | E25: Account Services - NOW | F25: Yes | O25: 5 | P25: 6.5 | Q25: 8 | R25: 11.5 | S25: 2.5 | T25: 1 | U25: 2.5 | V25: =AVERAGE(G25:U25) -> 5.2857143 | W25: =AVERAGE(I25:U25) -> 5.2857143 | X25: =AVERAGE(O25:U25) -> 5.2857143 | AC25: 8.5 | AD25: 6.5 | AE25: =AVERAGE(Y25:AD25) -> 7.5 | AF25: 10 | AL25: =AVERAGE(AF25:AK25) -> 10 | AU25: =COUNT(G25:U25) -> 7 | AV25: =IF(AU25<5,"Low coverage",IF(AU25<15,"Partial","Full")) -> Partial
A26: 25 | B26: IXT | C26: Agile Portfolio Mgmt | E26: Scrum Master | AU26: =COUNT(G26:U26) -> 0 | AV26: =IF(AU26<5,"Low coverage",IF(AU26<15,"Partial","Full")) -> Low coverage
A27: 26 | B27: IXT | C27: Payment & Billing | E27: Scrum Master | AU27: =COUNT(G27:U27) -> 0 | AV27: =IF(AU27<5,"Low coverage",IF(AU27<15,"Partial","Full")) -> Low coverage
A28: 27 | B28: IXT | C28: Payment & Billing | E28: DBA Scrum | AU28: =COUNT(G28:U28) -> 0 | AV28: =IF(AU28<5,"Low coverage",IF(AU28<15,"Partial","Full")) -> Low coverage
A29: 28 | B29: IXT | C29: Field experience | D29: Field Experience | E29: NWT-FSM 2 (NOVA) | F29: Yes | AF29: 3.3333333 | AG29: 9 | AH29: 4 | AI29: 8.5 | AJ29: 7.5 | AK29: 3.5 | AL29: =AVERAGE(AF29:AK29) -> 5.9722222 | AM29: 7 | AT29: =AVERAGE(AM29:AR29) -> 7 | AU29: =COUNT(G29:U29) -> 0 | AV29: =IF(AU29<5,"Low coverage",IF(AU29<15,"Partial","Full")) -> Low coverage
P31: 5 | V31: 14 | AW31: ⚠ UNATTRIBUTED DATA — values exist in this row (see original Sp columns) with no SL No, Domain, Workstream, or Application name. Cannot be attributed to any app/owner. See Data Quality Flags tab.
P32: 5 | V32: 10 | AW32: ⚠ UNATTRIBUTED DATA — values exist in this row (see original Sp columns) with no SL No, Domain, Workstream, or Application name. Cannot be attributed to any app/owner. See Data Quality Flags tab.
P33: 10 | V33: 10 | AW33: ⚠ UNATTRIBUTED DATA — values exist in this row (see original Sp columns) with no SL No, Domain, Workstream, or Application name. Cannot be attributed to any app/owner. See Data Quality Flags tab.
P34: 10 | V34: =AVERAGE(V31:V33) -> 11.333333 | AW34: ⚠ UNATTRIBUTED DATA — values exist in this row (see original Sp columns) with no SL No, Domain, Workstream, or Application name. Cannot be attributed to any app/owner. See Data Quality Flags tab.
P35: 10 | V35: =V34*0.8 -> 9.0666667 | AW35: ⚠ UNATTRIBUTED DATA — values exist in this row (see original Sp columns) with no SL No, Domain, Workstream, or Application name. Cannot be attributed to any app/owner. See Data Quality Flags tab.
P37: =AVERAGE(P31:P35) -> 8 | AW37: ⚠ UNATTRIBUTED DATA — values exist in this row (see original Sp columns) with no SL No, Domain, Workstream, or Application name. Cannot be attributed to any app/owner. See Data Quality Flags tab.
P38: =P37*0.8 -> 6.4 | AW38: ⚠ UNATTRIBUTED DATA — values exist in this row (see original Sp columns) with no SL No, Domain, Workstream, or Application name. Cannot be attributed to any app/owner. See Data Quality Flags tab.

Sheet Pivot Productivity
A1: Workstream | B1: - all - | H1: 26Q2 Vs 26Q1
A2: Active App | B2: Yes | H2: 26Q2 Vs 25Q4
A4: Row Labels | B4: Q3 (SP 14 to 19) | C4: Q4 (SP 20 to 26) | D4: Q1 (SP 1 to 6) | E4: Q2 (SP 7 to 12) | F4: Q3 (SP 13 to 15)
A5: Account Services | B5: 8.7738095 | C5: 8.7738095 | D5: 10.300926 | E5: 11.280556 | F5: 10.383333
A6: Account Services - BRE | B6: 12.142857 | C6: 12.142857 | D6: 11.666667 | E6: 13.666667 | F6: 11.5
A7: Account Services - NOW | B7: 5.2857143 | C7: 5.2857143 | D7: 7.5 | E7: 10
A8: Account Services - XM PDF | B8: 8.8928571 | C8: 8.8928571 | D8: 11.736111 | E8: 10.175 | F8: 9.2666667
A9: Assisted Tools | B9: 5.9772746 | C9: 6.3376648 | D9: 7.240114 | E9: 7.3777417 | F9: 7.041
A10: CPOS | C10: 4.9444444 | D10: 6.2083333 | E10: 6.425 | F10: 5.0833333
A11: XM Velocity 1/Xceeders | B11: 4.2307692 | C11: 5.6754945 | D11: 7.0167949 | E11: 7.2720513 | F11: 7.85
A12: XM Velocity 2/Xplorers | B12: 3.8 | C12: 4.2228571 | D12: 6.1705556 | E12: 6.6085653
A13: XM360 CBM/Phoenix | B13: 6.0714286 | C13: 7.3921429 | D13: 7.4375 | E13: 5.8141667 | F13: 5.295
A14: XM360 Supersonix | B14: 6.1407407 | C14: 7.4598412 | D14: 7.6258333 | E14: 7.48 | F14: 5.3766667
A15: Xumo | B15: 9.6434343 | C15: 8.3312088 | D15: 8.9816667 | E15: 10.666667 | F15: 11.6
A16: BXT | B16: 5.9259259 | C16: 4.8228571 | D16: 6.285 | E16: 6.7955556 | F16: 9.17
A17: DevOps | B17: 5.9259259 | C17: 4.8228571 | D17: 6.285 | E17: 6.7955556 | F17: 9.17
A18: Field Experience | B18: 7.7582353 | C18: 7.3637872 | D18: 7.0857143 | E18: 6.5308889 | F18: 7.4108333
A19: NWT - Core | B19: 8.55 | C19: 8.1142857 | D19: 8.06 | E19: 4.2966667
A20: NWT - PSNB | B20: 8.4166667 | C20: 8.7071429 | D20: 7.3916667 | E20: 5.875 | F20: 5.5
A21: NWT - UI | B21: 8.6862745 | C21: 7.180663 | D21: 7.7666667 | E21: 8.4222222 | F21: 8.11
A22: NWT-FSM | B22: 5.38 | C22: 5.4530571 | D22: 5.1245238 | E22: 8.0883333 | F22: 9.0333333
A23: NWT-FSM 2 (NOVA) | E23: 5.9722222 | F23: 7
A24: Platform | B24: 7.1603704 | C24: 6.6180272 | D24: 6.6549365 | E24: 8.2755079 | F24: 8.8333016
A25: Celestial (Titan) | B25: 11.416667 | C25: 10.514286 | D25: 11.828571 | E25: 13.033333 | F25: 14.066667
A26: Celestial (Universal) | B26: 7.6944444 | C26: 7.9877551 | D26: 8.8733333 | E26: 9.4514286 | F26: 10.190952
A27: Flow Engine (optimus) | B27: 4.4166667 | C27: 4.2214286 | D27: 4.4166667 | E27: 4.2916667 | F27: 4.5
A28: Flow Engine (prometheus) | B28: 3.0240741 | C28: 4.2238095 | D28: 3.9066667 | E28: 4.6011111 | F28: 5.4088889
A29: Right Answers | B29: 9.25 | C29: 6.1428571 | D29: 4.2494444 | E29: 10 | F29: 10
A30: XRM | B30: 5.2893939 | C30: 5.3741558 | D30: 5.7248822 | E30: 5.9776263 | F30: 5.7534343
A31: XRM - HSD Scrum | B31: 5.0666667 | C31: 4.5185714 | D31: 4.8905556 | E31: 5.6742424 | F31: 4.6333333
A32: XRM - Video Scrum | B32: 6.5909091 | C32: 6.1038961 | D32: 6.4148485 | E32: 6.3919697 | F32: 7.060303
A33: XRM - VOIXM Scrum | B33: 4.2106061 | C33: 5.5 | D33: 5.8692424 | E33: 5.8666667 | F33: 5.5666667
A34: Total Result | B34: 6.8969858 | C34: 6.7199103 | D34: 7.2463931 | E34: 7.6899363 | F34: 7.8105905

Sheet Master Data Velocity
A1: Domain | B1: Workstream | C1: QBR | D1: Application/Area | E1: Active App | F1: Story Points accepted in Sp 12 | G1: Story Points accepted in Sp 13 to date | H1: Story Points accepted in Sp 14 | I1: Story Points accepted in Sp 15 to date | J1: Developer/QA Count | K1: Story Points accepted in Sp 16 | L1: Story Points accepted in Sp 17 to date | M1: Developer/QA Count | N1: Story Points accepted in Sp 18 | O1: Story Points accepted in Sp 19 to date | P1: Developer/QA Count | Q1: Developer/QA Count in Q3 (SP 14 to 19) | R1: Total Story points Delivered across sprints in Q3(SP 14 to 19) | S1: # of Sprints in Q3 (SP 14 to 19) | T1: Avg USP / SP in Q3 (SP 14 to 19) | U1: Avg USP / Month In Q3(SP 14 to 19) | V1: Story Points accepted in Sp 20 | W1: Story Points accepted in Sp 21 | X1: Developer/QA Count | Y1: Story Points accepted in Sp 22 | Z1: Story Points accepted in Sp 23 | AA1: Story Points accepted in Sp 24 | AB1: Story Points accepted in Sp 25 | AC1: Story Points accepted in Sp 26 | AD1: Developer/QA Count in Q4 (SP 20 to 26) | AE1: Total Story points Delivered across sprints in Q4(SP 20 to 26) | AF1: # of Sprints in Q4 (SP 20 to 26) | AG1: Avg USP / SP in Q4 (SP 20 to 26) | AH1: Avg USP / Month In Q4(SP 20 to 26) | AI1: Developer/QA Count | AJ1: Total Story points Delivered across sprints | AK1: # of Sprints | AL1: Avg USP / SP | AM1: Avg USP / Month | AN1: Story Points accepted in Sp 1 | AO1: Story Points accepted in Sp 2 to date | AP1: Story Points accepted in Sp 3 | AQ1: Story Points accepted in Sp 4 to date | AR1: Story Points accepted in Sp 5 | AS1: Story Points accepted in Sp 6 | AT1: Developer/QA Count in Q1 | AU1: Total Story points Delivered across sprints in Q1 | AV1: # of Sprints in Q1 | AW1: Avg USP / SP in Q1 (SP 1 to 6) | AX1: Avg USP / Month In Q1 (SP 1 to 6) | AY1: Story Points accepted in 7 to date | AZ1: Story Points accepted in 8 to date | BA1: Story Points accepted in 9 to date | BB1: Story Points accepted in 10 to date | BC1: Story Points accepted in 11 to date | BD1: Story Points accepted in 12 to date | BE1: Developer/QA Count in Q2 | BF1: Total Story points Delivered across sprints in Q2 | BG1: # of Sprints in Q2 | BH1: Avg USP / SP in Q2 (SP 7 to 12) | BI1: Avg USP / Month In Q2(SP 7 to 12) | BJ1: RAG (Q1 vs Q2 Δ) | BK1: AVG SP in Q1 with 4 SP | BL1: RAG Q1(4SP) vs Q2 Δ | BM1: Story Points accepted in 13 to date | BN1: Story Points accepted in 14 to date | BO1: Story Points accepted in 15 to date | BP1: Story Points accepted in 16 to date | BQ1: Story Points accepted in 17 to date | BR1: Story Points accepted in 18 to date | BS1: Story Points accepted in 18 to date | BT1: Developer/QA Count in Q2 | BU1: Total Story points Delivered across sprints in Q2 | BV1: # of Sprints in Q2 | BW1: Avg USP / SP in Q3 (SP 13 to 15) | BX1: Avg USP / Month In Q3(SP 13 to 15)
A2: IXT | B2: CEUI | C2: Assisted Tools | D2: CPOS | E2: Yes | Q2: 0 | R2: =SUM(N2:P2) -> 0 | S2: 0 | T2: 0 | U2: 0 | AA2: 28 | AB2: 22 | AC2: 39 | AD2: 6 | AE2: =SUM(AA2:AC2) -> 89 | AF2: 3 | AG2: =AE2/AF2 -> 29.666667 | AH2: =AG2*2 -> 59.333333 | AI2: 6 | AJ2: =F2+G2+H2+I2+K2+L2+N2+O2+V2+W2+Y2+Z2+AA2+AB2+AC2 -> 89 | AK2: 3 | AL2: =AJ2/AK2 -> 29.666667 | AM2: =AL2*2 -> 59.333333 | AN2: 13 | AO2: 27 | AP2: 33 | AQ2: 22 | AR2: 12 | AS2: 42 | AT2: 4 | AU2: =SUM(AN2:AS2) -> 149 | AV2: 6 | AW2: =AU2/AV2 -> 24.833333 | AX2: =AW2*2 -> 49.666667 | AY2: 29 | AZ2: 23 | BA2: 14 | BB2: 13 | BC2: 27 | BD2: 32 | BE2: 4 | BF2: =SUM(AY2:BD2) -> 138 | BG2: 6 | BH2: =BF2/BG2 -> 23 | BI2: =BH2*2 -> 46 | BJ2: =IF(OR($D2="",$AW2="",$BH2=""),"",IFERROR(IF(VALUE($BH2)>VALUE($AW2),"▲ "&TEXT(VALUE($BH2)-VALUE($AW2),"0.00"),IF(VALUE($BH2)<VALUE($AW2),"▼ "&TEXT(VALUE($AW2)-VALUE($BH2),"0.00"),"● 0.00")),"")) -> ▼ 1.83 | BK2: =SUM(AN2:AQ2)/4 -> 23.75 | BL2: =IF(OR(BK2="",BH2="",NOT(ISNUMBER(BK2)),NOT(ISNUMBER(BH2))),"",IF(BH2>BK2,"▲ "&TEXT(ABS(BH2-BK2),"0.00"),IF(BH2<BK2,"▼ "&TEXT(ABS(BH2-BK2),"0.00"),"● 0.00"))) -> ▼ 0.75 | BM2: 32 | BN2: 29 | BT2: 4 | BU2: =SUM(BM2:BS2) -> 61 | BV2: 2 | BW2: =BU2/BV2 -> 30.5 | BX2: =BW2*2 -> 61
A3: IXT | B3: CEUI | C3: Assisted Tools | D3: Xumo | E3: Yes | F3: 67 | G3: 74 | H3: 75 | I3: 55 | J3: 7 | K3: 49 | L3: 54 | M3: 6 | N3: 54 | O3: 56 | P3: 6 | Q3: 6.5 | R3: =SUM(H3:O3) -> 356 | S3: 6 | T3: =R3/S3 -> 59.333333 | U3: =T3*2 -> 118.66667 | V3: 59 | W3: 53 | X3: 6.5 | Y3: 52 | Z3: 67 | AA3: 69 | AB3: 55 | AC3: 24 | AD3: 6.5 | AE3: =SUM(V3:AC3) -> 385.5 | AF3: 7 | AG3: =AE3/AF3 -> 55.071429 | AH3: =AG3*2 -> 110.14286 | AI3: 6.5 | AJ3: =F3+G3+H3+I3+K3+L3+N3+O3+V3+W3+Y3+Z3+AA3+AB3+AC3 -> 863 | AK3: 15 | AL3: =AJ3/AK3 -> 57.533333 | AM3: =AL3*2 -> 115.06667 | AN3: 43 | AO3: 40 | AP3: 46 | AQ3: 52 | AR3: 49 | AS3: 52 | AT3: 5.5 | AU3: =SUM(AN3:AS3) -> 282 | AV3: 6 | AW3: =AU3/AV3 -> 47 | AX3: =AW3*2 -> 94 | AY3: 50 | AZ3: 53 | BA3: 53 | BB3: 52 | BC3: 53 | BD3: 59 | BE3: 5 | BF3: =SUM(AY3:BD3) -> 320 | BG3: 6 | BH3: =BF3/BG3 -> 53.333333 | BI3: =BH3*2 -> 106.66667 | BJ3: =IF(OR($D3="",$AW3="",$BH3=""),"",IFERROR(IF(VALUE($BH3)>VALUE($AW3),"▲ "&TEXT(VALUE($BH3)-VALUE($AW3),"0.00"),IF(VALUE($BH3)<VALUE($AW3),"▼ "&TEXT(VALUE($AW3)-VALUE($BH3),"0.00"),"● 0.00")),"")) -> ▲ 6.33 | BK3: =SUM(AN3:AQ3)/4 -> 45.25 | BL3: =IF(OR(BK3="",BH3="",NOT(ISNUMBER(BK3)),NOT(ISNUMBER(BH3))),"",IF(BH3>BK3,"▲ "&TEXT(ABS(BH3-BK3),"0.00"),IF(BH3<BK3,"▼ "&TEXT(ABS(BH3-BK3),"0.00"),"● 0.00"))) -> ▲ 8.08 | BM3: 54 | BN3: 69 | BO3: 51 | BT3: 5 | BU3: =SUM(BM3:BS3) -> 174 | BV3: 3 | BW3: =BU3/BV3 -> 58 | BX3: =BW3*2 -> 116
A4: IXT | B4: CEUI | C4: Platform | D4: Flow Engine (prometheus) | E4: Yes | F4: 28 | G4: 28 | H4: 20 | I4: 26 | J4: 9 | K4: 30 | L4: 27 | M4: 9 | N4: 22 | O4: 39 | P4: 9 | Q4: 9 | R4: =SUM(H4:O4) -> 182 | S4: 6 | T4: =R4/S4 -> 30.333333 | U4: =T4*2 -> 60.666667 | V4: 35 | W4: 45 | X4: 9 | Y4: 36 | Z4: 32 | AA4: 36.5 | AB4: 35.5 | AC4: 46 | AD4: 9 | AE4: =SUM(V4:AC4) -> 275 | AF4: 7 | AG4: =AE4/AF4 -> 39.285714 | AH4: =AG4*2 -> 78.571429 | AI4: 9 | AJ4: =F4+G4+H4+I4+K4+L4+N4+O4+V4+W4+Y4+Z4+AA4+AB4+AC4 -> 486 | AK4: 15 | AL4: =AJ4/AK4 -> 32.4 | AM4: =AL4*2 -> 64.8 | AN4: 27 | AO4: 39 | AP4: 36 | AQ4: 39 | AR4: 38 | AS4: 32 | AT4: 9 | AU4: =SUM(AN4:AS4) -> 211 | AV4: 6 | AW4: =AU4/AV4 -> 35.166667 | AX4: =AW4*2 -> 70.333333 | AY4: 37 | AZ4: 34 | BA4: 37 | BB4: 44 | BC4: 48 | BD4: 48.5 | BE4: 9 | BF4: =SUM(AY4:BD4) -> 248.5 | BG4: 6 | BH4: =BF4/BG4 -> 41.416667 | BI4: =BH4*2 -> 82.833333 | BJ4: =IF(OR($D4="",$AW4="",$BH4=""),"",IFERROR(IF(VALUE($BH4)>VALUE($AW4),"▲ "&TEXT(VALUE($BH4)-VALUE($AW4),"0.00"),IF(VALUE($BH4)<VALUE($AW4),"▼ "&TEXT(VALUE($AW4)-VALUE($BH4),"0.00"),"● 0.00")),"")) -> ▲ 6.25 | BK4: =SUM(AN4:AQ4)/4 -> 35.25 | BL4: =IF(OR(BK4="",BH4="",NOT(ISNUMBER(BK4)),NOT(ISNUMBER(BH4))),"",IF(BH4>BK4,"▲ "&TEXT(ABS(BH4-BK4),"0.00"),IF(BH4<BK4,"▼ "&TEXT(ABS(BH4-BK4),"0.00"),"● 0.00"))) -> ▲ 6.17 | BM4: 45 | BN4: 50 | BO4: 51 | BT4: 9 | BU4: =SUM(BM4:BS4) -> 146 | BV4: 3 | BW4: =BU4/BV4 -> 48.666667 | BX4: =BW4*2 -> 97.333333
A5: IXT | B5: CEUI | C5: Platform | D5: Flow Engine (optimus) | E5: Yes | F5: 8.5 | G5: 8 | H5: 10.5 | I5: 10 | J5: 2 | K5: 8.5 | L5: 8 | M5: 2 | N5: 6.5 | O5: 9.5 | P5: 2 | Q5: 2 | R5: =SUM(H5:O5) -> 57 | S5: 6 | T5: =R5/S5 -> 9.5 | U5: =T5*2 -> 19 | V5: 8.5 | W5: 8 | X5: 2 | Y5: 7 | Z5: 10 | AA5: 9 | AB5: 8.5 | AC5: 8 | AD5: 2 | AE5: =SUM(V5:AC5) -> 61 | AF5: 7 | AG5: =AE5/AF5 -> 8.7142857 | AH5: =AG5*2 -> 17.428571 | AI5: 2 | AJ5: =F5+G5+H5+I5+K5+L5+N5+O5+V5+W5+Y5+Z5+AA5+AB5+AC5 -> 128.5 | AK5: 15 | AL5: =AJ5/AK5 -> 8.5666667 | AM5: =AL5*2 -> 17.133333 | AN5: 6.5 | AO5: 8.5 | AP5: 9.5 | AQ5: 10 | AR5: 12 | AS5: 6.5 | AT5: 2 | AU5: =SUM(AN5:AS5) -> 53 | AV5: 6 | AW5: =AU5/AV5 -> 8.8333333 | AX5: =AW5*2 -> 17.666667 | AY5: 8.5 | AZ5: 8 | BA5: 9 | BB5: 10 | BC5: 8 | BD5: 8 | BE5: 2 | BF5: =SUM(AY5:BD5) -> 51.5 | BG5: 6 | BH5: =BF5/BG5 -> 8.5833333 | BI5: =BH5*2 -> 17.166667 | BJ5: =IF(OR($D5="",$AW5="",$BH5=""),"",IFERROR(IF(VALUE($BH5)>VALUE($AW5),"▲ "&TEXT(VALUE($BH5)-VALUE($AW5),"0.00"),IF(VALUE($BH5)<VALUE($AW5),"▼ "&TEXT(VALUE($AW5)-VALUE($BH5),"0.00"),"● 0.00")),"")) -> ▼ 0.25 | BK5: =SUM(AN5:AQ5)/4 -> 8.625 | BL5: =IF(OR(BK5="",BH5="",NOT(ISNUMBER(BK5)),NOT(ISNUMBER(BH5))),"",IF(BH5>BK5,"▲ "&TEXT(ABS(BH5-BK5),"0.00"),IF(BH5<BK5,"▼ "&TEXT(ABS(BH5-BK5),"0.00"),"● 0.00"))) -> ▼ 0.04 | BM5: 6.5 | BN5: 10 | BO5: 10.5 | BT5: 2 | BU5: =SUM(BM5:BS5) -> 27 | BV5: 3 | BW5: =BU5/BV5 -> 9 | BX5: =BW5*2 -> 18
A6: IXT | B6: CEUI | C6: Platform | D6: Celestial (Titan) | E6: Yes | F6: 47 | G6: 43 | H6: 60 | I6: 75 | J6: 6 | K6: 80 | L6: 47 | M6: 6 | N6: 82 | O6: 67 | P6: 6 | Q6: 5 | R6: =SUM(H6:O6) -> 423 | S6: 6 | T6: =R6/S6 -> 70.5 | U6: =T6*2 -> 141 | V6: 56 | W6: 57 | X6: 5 | Y6: 54 | Z6: 50 | AA6: 60 | AB6: 55 | AC6: 36 | AD6: 5 | AE6: =SUM(V6:AC6) -> 373 | AF6: 7 | AG6: =AE6/AF6 -> 53.285714 | AH6: =AG6*2 -> 106.57143 | AI6: 5 | AJ6: =F6+G6+H6+I6+K6+L6+N6+O6+V6+W6+Y6+Z6+AA6+AB6+AC6 -> 869 | AK6: 15 | AL6: =AJ6/AK6 -> 57.933333 | AM6: =AL6*2 -> 115.86667 | AN6: 57 | AO6: 65 | AP6: 63 | AQ6: 60 | AR6: 62 | AS6: 67 | AT6: 5 | AU6: =SUM(AN6:AS6) -> 374 | AV6: 6 | AW6: =AU6/AV6 -> 62.333333 | AX6: =AW6*2 -> 124.66667 | AY6: 64 | AZ6: 71 | BA6: 66 | BB6: 70 | BC6: 60 | BD6: 60 | BE6: 5 | BF6: =SUM(AY6:BD6) -> 391 | BG6: 6 | BH6: =BF6/BG6 -> 65.166667 | BI6: =BH6*2 -> 130.33333 | BJ6: =IF(OR($D6="",$AW6="",$BH6=""),"",IFERROR(IF(VALUE($BH6)>VALUE($AW6),"▲ "&TEXT(VALUE($BH6)-VALUE($AW6),"0.00"),IF(VALUE($BH6)<VALUE($AW6),"▼ "&TEXT(VALUE($AW6)-VALUE($BH6),"0.00"),"● 0.00")),"")) -> ▲ 2.83 | BK6: =SUM(AN6:AQ6)/4 -> 61.25 | BL6: =IF(OR(BK6="",BH6="",NOT(ISNUMBER(BK6)),NOT(ISNUMBER(BH6))),"",IF(BH6>BK6,"▲ "&TEXT(ABS(BH6-BK6),"0.00"),IF(BH6<BK6,"▼ "&TEXT(ABS(BH6-BK6),"0.00"),"● 0.00"))) -> ▲ 3.92 | BM6: 66 | BN6: 56 | BO6: 60 | BT6: 4 | BU6: =SUM(BM6:BS6) -> 182 | BV6: 3 | BW6: =BU6/BV6 -> 60.666667 | BX6: =BW6*2 -> 121.33333
A7: IXT | B7: CEUI | C7: Platform | D7: Celestial (Universal) | E7: Yes | F7: 42 | G7: 38 | H7: 44 | I7: 51 | J7: 6 | K7: 49 | L7: 48 | M7: 6 | N7: 35 | O7: 50 | P7: 6 | Q7: 7 | R7: =SUM(H7:O7) -> 289 | S7: 6 | T7: =R7/S7 -> 48.166667 | U7: =T7*2 -> 96.333333 | V7: 58 | W7: 55 | X7: 7 | Y7: 58 | Z7: 50 | AA7: 52 | AB7: 53 | AC7: 65 | AD7: 7 | AE7: =SUM(V7:AC7) -> 398 | AF7: 7 | AG7: =AE7/AF7 -> 56.857143 | AH7: =AG7*2 -> 113.71429 | AI7: 7 | AJ7: =F7+G7+H7+I7+K7+L7+N7+O7+V7+W7+Y7+Z7+AA7+AB7+AC7 -> 748 | AK7: 15 | AL7: =AJ7/AK7 -> 49.866667 | AM7: =AL7*2 -> 99.733333 | AN7: 63 | AO7: 58 | AP7: 64 | AQ7: 68 | AR7: 62 | AS7: 66 | AT7: 7 | AU7: =SUM(AN7:AS7) -> 381 | AV7: 6 | AW7: =AU7/AV7 -> 63.5 | AX7: =AW7*2 -> 127 | AY7: 63 | AZ7: 65 | BA7: 64 | BB7: 67 | BC7: 71 | BD7: 67 | BE7: 7 | BF7: =SUM(AY7:BD7) -> 397 | BG7: 6 | BH7: =BF7/BG7 -> 66.166667 | BI7: =BH7*2 -> 132.33333 | BJ7: =IF(OR($D7="",$AW7="",$BH7=""),"",IFERROR(IF(VALUE($BH7)>VALUE($AW7),"▲ "&TEXT(VALUE($BH7)-VALUE($AW7),"0.00"),IF(VALUE($BH7)<VALUE($AW7),"▼ "&TEXT(VALUE($AW7)-VALUE($BH7),"0.00"),"● 0.00")),"")) -> ▲ 2.67 | BK7: =SUM(AN7:AQ7)/4 -> 63.25 | BL7: =IF(OR(BK7="",BH7="",NOT(ISNUMBER(BK7)),NOT(ISNUMBER(BH7))),"",IF(BH7>BK7,"▲ "&TEXT(ABS(BH7-BK7),"0.00"),IF(BH7<BK7,"▼ "&TEXT(ABS(BH7-BK7),"0.00"),"● 0.00"))) -> ▲ 2.92 | BM7: 74 | BN7: 69 | BO7: 71 | BT7: 7 | BU7: =SUM(BM7:BS7) -> 214 | BV7: 3 | BW7: =BU7/BV7 -> 71.333333 | BX7: =BW7*2 -> 142.66667
A8: IXT | B8: CEUI | C8: Platform | D8: Right Answers | E8: Yes | F8: 17 | G8: 18 | H8: 15 | I8: 17 | J8: 2 | K8: 18 | L8: 18 | M8: 2 | N8: 17 | O8: 26 | P8: 2 | Q8: 2 | R8: =SUM(H8:O8) -> 115 | S8: 6 | T8: =R8/S8 -> 19.166667 | U8: =T8*2 -> 38.333333 | V8: 18 | W8: 15 | X8: 2 | Y8: 10 | Z8: 7 | AA8: 13 | AB8: 8 | AC8: 12 | AD8: 2 | AE8: =SUM(V8:AC8) -> 85 | AF8: 7 | AG8: =AE8/AF8 -> 12.142857 | AH8: =AG8*2 -> 24.285714 | AI8: 2 | AJ8: =F8+G8+H8+I8+K8+L8+N8+O8+V8+W8+Y8+Z8+AA8+AB8+AC8 -> 229 | AK8: 15 | AL8: =AJ8/AK8 -> 15.266667 | AM8: =AL8*2 -> 30.533333 | AN8: 6 | AO8: 9 | AP8: 4 | AQ8: 4 | AR8: 22 | AS8: 20 | AT8: 2 | AU8: =SUM(AN8:AS8) -> 65 | AV8: 6 | AW8: =AU8/AV8 -> 10.833333 | AX8: =AW8*2 -> 21.666667 | AY8: 23 | AZ8: 25 | BA8: 11 | BB8: 21 | BC8: 19 | BD8: 21 | BE8: 2 | BF8: =SUM(AY8:BD8) -> 120 | BG8: 6 | BH8: =BF8/BG8 -> 20 | BI8: =BH8*2 -> 40 | BJ8: =IF(OR($D8="",$AW8="",$BH8=""),"",IFERROR(IF(VALUE($BH8)>VALUE($AW8),"▲ "&TEXT(VALUE($BH8)-VALUE($AW8),"0.00"),IF(VALUE($BH8)<VALUE($AW8),"▼ "&TEXT(VALUE($AW8)-VALUE($BH8),"0.00"),"● 0.00")),"")) -> ▲ 9.17 | BK8: =SUM(AN8:AQ8)/4 -> 5.75 | BL8: =IF(OR(BK8="",BH8="",NOT(ISNUMBER(BK8)),NOT(ISNUMBER(BH8))),"",IF(BH8>BK8,"▲ "&TEXT(ABS(BH8-BK8),"0.00"),IF(BH8<BK8,"▼ "&TEXT(ABS(BH8-BK8),"0.00"),"● 0.00"))) -> ▲ 14.25 | BM8: 22 | BN8: 18 | BO8: 20 | BT8: 2 | BU8: =SUM(BM8:BS8) -> 60 | BV8: 3 | BW8: =BU8/BV8 -> 20 | BX8: =BW8*2 -> 40
A9: IXT | B9: CEUI | C9: Assisted Tools | D9: XM360 CBM/Phoenix | E9: Yes | F9: 27 | G9: 30 | H9: 21 | I9: 63 | J9: 7 | K9: 24 | L9: 55 | M9: 7 | N9: 35 | O9: 57 | P9: 7 | Q9: 8 | R9: =SUM(H9:O9) -> 269 | S9: 6 | T9: =R9/S9 -> 44.833333 | U9: =T9*2 -> 89.666667 | V9: 67 | W9: 66 | X9: 8 | Y9: 63 | Z9: 78 | AA9: 60 | AB9: 39 | AC9: 41 | AD9: 8 | AE9: =SUM(V9:AC9) -> 422 | AF9: 7 | AG9: =AE9/AF9 -> 60.285714 | AH9: =AG9*2 -> 120.57143 | AI9: 8 | AJ9: =F9+G9+H9+I9+K9+L9+N9+O9+V9+W9+Y9+Z9+AA9+AB9+AC9 -> 726 | AK9: 15 | AL9: =AJ9/AK9 -> 48.4 | AM9: =AL9*2 -> 96.8 | AN9: 30 | AO9: 58 | AP9: 68 | AQ9: 81 | AR9: 59 | AS9: 61 | AT9: 8 | AU9: =SUM(AN9:AS9) -> 357 | AV9: 6 | AW9: =AU9/AV9 -> 59.5 | AX9: =AW9*2 -> 119 | AY9: 58 | AZ9: 41 | BA9: 51 | BB9: 41 | BC9: 39 | BD9: 49 | BE9: 8 | BF9: =SUM(AY9:BD9) -> 279 | BG9: 6 | BH9: =BF9/BG9 -> 46.5 | BI9: =BH9*2 -> 93 | BJ9: =IF(OR($D9="",$AW9="",$BH9=""),"",IFERROR(IF(VALUE($BH9)>VALUE($AW9),"▲ "&TEXT(VALUE($BH9)-VALUE($AW9),"0.00"),IF(VALUE($BH9)<VALUE($AW9),"▼ "&TEXT(VALUE($AW9)-VALUE($BH9),"0.00"),"● 0.00")),"")) -> ▼ 13.00 | BK9: =SUM(AN9:AQ9)/4 -> 59.25 | BL9: =IF(OR(BK9="",BH9="",NOT(ISNUMBER(BK9)),NOT(ISNUMBER(BH9))),"",IF(BH9>BK9,"▲ "&TEXT(ABS(BH9-BK9),"0.00"),IF(BH9<BK9,"▼ "&TEXT(ABS(BH9-BK9),"0.00"),"● 0.00"))) -> ▼ 12.75 | BM9: 41 | BN9: 47 | BO9: 39 | BT9: 8 | BU9: =SUM(BM9:BS9) -> 127 | BV9: 3 | BW9: =BU9/BV9 -> 42.333333 | BX9: =BW9*2 -> 84.666667
A10: IXT | B10: CEUI | C10: Assisted Tools | D10: XM360 Recovery/Reliability | E10: No | F10: 55 | G10: 50 | H10: 51 | I10: 43 | J10: 8 | K10: 45 | L10: 44 | M10: 8 | N10: 28 | O10: 38 | P10: 6.5 | Q10: 6.5 | R10: =SUM(H10:O10) -> 265 | S10: 6 | T10: =R10/S10 -> 44.166667 | U10: =T10*2 -> 88.333333 | V10: 45 | W10: 52 | X10: 6.5 | Y10: 59 | Z10: 55 | AA10: 51 | AB10: 50 | AC10: 45 | AD10: 6.5 | AE10: =SUM(V10:AC10) -> 363.5 | AF10: 7 | AG10: =AE10/AF10 -> 51.928571 | AH10: =AG10*2 -> 103.85714 | AI10: 6.5 | AJ10: =F10+G10+H10+I10+K10+L10+N10+O10+V10+W10+Y10+Z10+AA10+AB10+AC10 -> 711 | AK10: 15 | AL10: =AJ10/AK10 -> 47.4 | AM10: =AL10*2 -> 94.8 | AN10: 0 | AO10: 0 | AP10: 0 | AQ10: 0 | AR10: 0 | AS10: 0 | AT10: 0 | AU10: =SUM(AN10:AS10) -> 0 | AV10: 6 | AW10: =AU10/AV10 -> 0 | AX10: =AW10*2 -> 0 | BJ10: =IF(OR($D10="",$AW10="",$BH10=""),"",IFERROR(IF(VALUE($BH10)>VALUE($AW10),"▲ "&TEXT(VALUE($BH10)-VALUE($AW10),"0.00"),IF(VALUE($BH10)<VALUE($AW10),"▼ "&TEXT(VALUE($AW10)-VALUE($BH10),"0.00"),"● 0.00")),"")) | BK10: =SUM(AN10:AQ10)/4 -> 0 | BL10: =IF(OR(BK10="",BH10="",NOT(ISNUMBER(BK10)),NOT(ISNUMBER(BH10))),"",IF(BH10>BK10,"▲ "&TEXT(ABS(BH10-BK10),"0.00"),IF(BH10<BK10,"▼ "&TEXT(ABS(BH10-BK10),"0.00"),"● 0.00")))
A11: IXT | B11: CEUI | C11: Assisted Tools | D11: XM360 Supersonix | E11: Yes | F11: 27 | G11: 39 | H11: 58 | I11: 43 | J11: 7.5 | K11: 45 | L11: 47 | M11: 7.5 | N11: 28 | O11: 22 | P11: 4.5 | Q11: 4.5 | R11: =SUM(H11:O11) -> 258 | S11: 6 | T11: =R11/S11 -> 43 | U11: =T11*2 -> 86 | V11: 28 | W11: 32 | X11: 4.5 | Y11: 39 | Z11: 47 | AA11: 33 | AB11: 27 | AC11: 29 | AD11: 4.5 | AE11: =SUM(V11:AC11) -> 239.5 | AF11: 7 | AG11: =AE11/AF11 -> 34.214286 | AH11: =AG11*2 -> 68.428571 | AI11: 4.5 | AJ11: =F11+G11+H11+I11+K11+L11+N11+O11+V11+W11+Y11+Z11+AA11+AB11+AC11 -> 544 | AK11: 15 | AL11: =AJ11/AK11 -> 36.266667 | AM11: =AL11*2 -> 72.533333 | AN11: 27 | AO11: 62 | AP11: 66 | AQ11: 57 | AR11: 79 | AS11: 75 | AT11: 8 | AU11: =SUM(AN11:AS11) -> 366 | AV11: 6 | AW11: =AU11/AV11 -> 61 | AX11: =AW11*2 -> 122 | AY11: 59 | AZ11: 66 | BA11: 70 | BB11: 75 | BC11: 51 | BD11: 38 | BE11: 8 | BF11: =SUM(AY11:BD11) -> 359 | BG11: 6 | BH11: =BF11/BG11 -> 59.833333 | BI11: =BH11*2 -> 119.66667 | BJ11: =IF(OR($D11="",$AW11="",$BH11=""),"",IFERROR(IF(VALUE($BH11)>VALUE($AW11),"▲ "&TEXT(VALUE($BH11)-VALUE($AW11),"0.00"),IF(VALUE($BH11)<VALUE($AW11),"▼ "&TEXT(VALUE($AW11)-VALUE($BH11),"0.00"),"● 0.00")),"")) -> ▼ 1.17 | BK11: =SUM(AN11:AQ11)/4 -> 53 | BL11: =IF(OR(BK11="",BH11="",NOT(ISNUMBER(BK11)),NOT(ISNUMBER(BH11))),"",IF(BH11>BK11,"▲ "&TEXT(ABS(BH11-BK11),"0.00"),IF(BH11<BK11,"▼ "&TEXT(ABS(BH11-BK11),"0.00"),"● 0.00"))) -> ▲ 6.83 | BM11: 42 | BN11: 43 | BO11: 44 | BT11: 8 | BU11: =SUM(BM11:BS11) -> 129 | BV11: 3 | BW11: =BU11/BV11 -> 43 | BX11: =BW11*2 -> 86
A12: IXT | B12: CEUI | C12: Assisted Tools | D12: XM Velocity 1/Xceeders | E12: Yes | F12: 11 | G12: 41 | H12: 20 | I12: 16 | J12: 6.5 | K12: 42 | L12: 22 | M12: 6.5 | N12: 29 | O12: 36 | P12: 6.5 | Q12: 6.5 | R12: =SUM(H12:O12) -> 178 | S12: 6 | T12: =R12/S12 -> 29.666667 | U12: =T12*2 -> 59.333333 | V12: 46 | W12: 41 | X12: 6.5 | Y12: 20 | Z12: 46 | AA12: 37 | AB12: 42 | AC12: 26 | AD12: 6.5 | AE12: =SUM(V12:AC12) -> 264.5 | AF12: 7 | AG12: =AE12/AF12 -> 37.785714 | AH12: =AG12*2 -> 75.571429 | AI12: 6.5 | AJ12: =F12+G12+H12+I12+K12+L12+N12+O12+V12+W12+Y12+Z12+AA12+AB12+AC12 -> 475 | AK12: 15 | AL12: =AJ12/AK12 -> 31.666667 | AM12: =AL12*2 -> 63.333333 | AN12: 45 | AO12: 49 | AP12: 44 | AQ12: 55 | AR12: 41 | AS12: 47 | AT12: 6.5 | AU12: =SUM(AN12:AS12) -> 281 | AV12: 6 | AW12: =AU12/AV12 -> 46.833333 | AX12: =AW12*2 -> 93.666667 | AY12: 38 | AZ12: 38 | BA12: 37 | BB12: 59 | BC12: 49 | BD12: 54 | BE12: 6.5 | BF12: =SUM(AY12:BD12) -> 275 | BG12: 6 | BH12: =BF12/BG12 -> 45.833333 | BI12: =BH12*2 -> 91.666667 | BJ12: =IF(OR($D12="",$AW12="",$BH12=""),"",IFERROR(IF(VALUE($BH12)>VALUE($AW12),"▲ "&TEXT(VALUE($BH12)-VALUE($AW12),"0.00"),IF(VALUE($BH12)<VALUE($AW12),"▼ "&TEXT(VALUE($AW12)-VALUE($BH12),"0.00"),"● 0.00")),"")) -> ▼ 1.00 | BK12: =SUM(AN12:AQ12)/4 -> 48.25 | BL12: =IF(OR(BK12="",BH12="",NOT(ISNUMBER(BK12)),NOT(ISNUMBER(BH12))),"",IF(BH12>BK12,"▲ "&TEXT(ABS(BH12-BK12),"0.00"),IF(BH12<BK12,"▼ "&TEXT(ABS(BH12-BK12),"0.00"),"● 0.00"))) -> ▼ 2.42 | BM12: 64 | BN12: 99 | BO12: 96 | BT12: 11 | BU12: =SUM(BM12:BS12) -> 259 | BV12: 3 | BW12: =BU12/BV12 -> 86.333333 | BX12: =BW12*2 -> 172.66667
A13: IXT | B13: CEUI | C13: Assisted Tools | D13: XM Velocity 2/Xplorers | E13: Yes | F13: 24 | G13: 67 | H13: 40 | I13: 14 | J13: 7.5 | K13: 25 | L13: 25 | M13: 7.5 | N13: 32 | O13: 35 | P13: 7.5 | Q13: 7.5 | R13: =SUM(H13:O13) -> 186 | S13: 6 | T13: =R13/S13 -> 31 | U13: =T13*2 -> 62 | V13: 39 | W13: 21 | X13: 7.5 | Y13: 29 | Z13: 38 | AA13: 32 | AB13: 34 | AC13: 29 | AD13: 7.5 | AE13: =SUM(V13:AC13) -> 229.5 | AF13: 7 | AG13: =AE13/AF13 -> 32.785714 | AH13: =AG13*2 -> 65.571429 | AI13: 7.5 | AJ13: =F13+G13+H13+I13+K13+L13+N13+O13+V13+W13+Y13+Z13+AA13+AB13+AC13 -> 484 | AK13: 15 | AL13: =AJ13/AK13 -> 32.266667 | AM13: =AL13*2 -> 64.533333 | AN13: 46 | AO13: 37 | AP13: 36 | AQ13: 47 | AR13: 26 | AS13: 47 | AT13: 7.5 | AU13: =SUM(AN13:AS13) -> 239 | AV13: 6 | AW13: =AU13/AV13 -> 39.833333 | AX13: =AW13*2 -> 79.666667 | AY13: 41 | AZ13: 36.5 | BA13: 29 | BB13: 51 | BC13: 55 | BD13: 46 | BE13: 6 | BF13: =SUM(AY13:BD13) -> 258.5 | BG13: 6 | BH13: =BF13/BG13 -> 43.083333 | BI13: =BH13*2 -> 86.166667 | BJ13: =IF(OR($D13="",$AW13="",$BH13=""),"",IFERROR(IF(VALUE($BH13)>VALUE($AW13),"▲ "&TEXT(VALUE($BH13)-VALUE($AW13),"0.00"),IF(VALUE($BH13)<VALUE($AW13),"▼ "&TEXT(VALUE($AW13)-VALUE($BH13),"0.00"),"● 0.00")),"")) -> ▲ 3.25 | BK13: =SUM(AN13:AQ13)/4 -> 41.5 | BL13: =IF(OR(BK13="",BH13="",NOT(ISNUMBER(BK13)),NOT(ISNUMBER(BH13))),"",IF(BH13>BK13,"▲ "&TEXT(ABS(BH13-BK13),"0.00"),IF(BH13<BK13,"▼ "&TEXT(ABS(BH13-BK13),"0.00"),"● 0.00"))) -> ▲ 1.58 | BT13: 6 | BU13: =SUM(BM13:BS13) -> 0 | BV13: 3 | BW13: =BU13/BV13 -> 0 | BX13: =BW13*2 -> 0
A14: IXT | B14: Field experience | C14: Field Experience | D14: NWT - UI | E14: Yes | F14: 82 | G14: 58 | H14: 69 | I14: 66 | J14: 8.5 | K14: 76 | L14: 70 | M14: 8.5 | N14: 70 | O14: 92 | P14: 8.5 | Q14: 8.5 | R14: =SUM(H14:O14) -> 460 | S14: 6 | T14: =R14/S14 -> 76.666667 | U14: =T14*2 -> 153.33333 | V14: 50 | W14: 78 | X14: 8.5 | Y14: 56 | Z14: 63 | AA14: 68 | AB14: 59 | AC14: 54 | AD14: 8.5 | AE14: =SUM(V14:AC14) -> 436.5 | AF14: 7 | AG14: =AE14/AF14 -> 62.357143 | AH14: =AG14*2 -> 124.71429 | AI14: 8.5 | AJ14: =F14+G14+H14+I14+K14+L14+N14+O14+V14+W14+Y14+Z14+AA14+AB14+AC14 -> 1011 | AK14: 15 | AL14: =AJ14/AK14 -> 67.4 | AM14: =AL14*2 -> 134.8 | AN14: 63 | AO14: 43 | AP14: 72 | AQ14: 63 | AR14: 51 | AS14: 42 | AT14: 8.5 | AU14: =SUM(AN14:AS14) -> 334 | AV14: 6 | AW14: =AU14/AV14 -> 55.666667 | AX14: =AW14*2 -> 111.33333 | AY14: 39 | AZ14: 48 | BA14: 37 | BB14: 67 | BC14: 30 | BD14: 44 | BE14: 5 | BF14: =SUM(AY14:BD14) -> 265 | BG14: 6 | BH14: =BF14/BG14 -> 44.166667 | BI14: =BH14*2 -> 88.333333 | BJ14: =IF(OR($D14="",$AW14="",$BH14=""),"",IFERROR(IF(VALUE($BH14)>VALUE($AW14),"▲ "&TEXT(VALUE($BH14)-VALUE($AW14),"0.00"),IF(VALUE($BH14)<VALUE($AW14),"▼ "&TEXT(VALUE($AW14)-VALUE($BH14),"0.00"),"● 0.00")),"")) -> ▼ 11.50 | BK14: =SUM(AN14:AQ14)/4 -> 60.25 | BL14: =IF(OR(BK14="",BH14="",NOT(ISNUMBER(BK14)),NOT(ISNUMBER(BH14))),"",IF(BH14>BK14,"▲ "&TEXT(ABS(BH14-BK14),"0.00"),IF(BH14<BK14,"▼ "&TEXT(ABS(BH14-BK14),"0.00"),"● 0.00"))) -> ▼ 16.08 | BM14: 35 | BN14: 55 | BO14: 65 | BT14: 6.5 | BU14: =SUM(BM14:BS14) -> 155 | BV14: 3 | BW14: =BU14/BV14 -> 51.666667 | BX14: =BW14*2 -> 103.33333
A15: IXT | B15: Field experience | C15: Field Experience | D15: NWT-FSM | E15: Yes | I15: 23 | J15: 3.5 | K15: 17 | L15: 20 | M15: 3.5 | N15: 14 | O15: 20 | P15: 3.5 | Q15: 3.5 | R15: =SUM(H15:O15) -> 101 | S15: 5 | T15: =R15/S15 -> 20.2 | U15: =T15*2 -> 40.4 | V15: 27 | W15: 20 | X15: 3.5 | Y15: 10 | Z15: 16 | AA15: 18 | AB15: 10 | AC15: 24 | AD15: 3.5 | AE15: =SUM(V15:AC15) -> 128.5 | AF15: 7 | AG15: =AE15/AF15 -> 18.357143 | AH15: =AG15*2 -> 36.714286 | AI15: 3.5 | AJ15: =F15+G15+H15+I15+K15+L15+N15+O15+V15+W15+Y15+Z15+AA15+AB15+AC15 -> 219 | AK15: 12 | AL15: =AJ15/AK15 -> 18.25 | AM15: =AL15*2 -> 36.5 | AN15: 6 | AO15: 16 | AP15: 16 | AQ15: 21 | AR15: 22 | AS15: 17 | AT15: 3.5 | AU15: =SUM(AN15:AS15) -> 98 | AV15: 6 | AW15: =AU15/AV15 -> 16.333333 | AX15: =AW15*2 -> 32.666667 | AY15: 23 | AZ15: 21 | BA15: 16 | BB15: 24 | BC15: 17 | BD15: 27 | BE15: 2.5 | BF15: =SUM(AY15:BD15) -> 128 | BG15: 6 | BH15: =BF15/BG15 -> 21.333333 | BI15: =BH15*2 -> 42.666667 | BJ15: =IF(OR($D15="",$AW15="",$BH15=""),"",IFERROR(IF(VALUE($BH15)>VALUE($AW15),"▲ "&TEXT(VALUE($BH15)-VALUE($AW15),"0.00"),IF(VALUE($BH15)<VALUE($AW15),"▼ "&TEXT(VALUE($AW15)-VALUE($BH15),"0.00"),"● 0.00")),"")) -> ▲ 5.00 | BK15: =SUM(AN15:AQ15)/4 -> 14.75 | BL15: =IF(OR(BK15="",BH15="",NOT(ISNUMBER(BK15)),NOT(ISNUMBER(BH15))),"",IF(BH15>BK15,"▲ "&TEXT(ABS(BH15-BK15),"0.00"),IF(BH15<BK15,"▼ "&TEXT(ABS(BH15-BK15),"0.00"),"● 0.00"))) -> ▲ 6.58 | BM15: 25 | BN15: 39 | BO15: 38 | BT15: 4.5 | BU15: =SUM(BM15:BS15) -> 102 | BV15: 3 | BW15: =BU15/BV15 -> 34 | BX15: =BW15*2 -> 68
A16: IXT | B16: Field experience | C16: Field Experience | D16: NWT - PSNB | E16: Yes | F16: 17 | G16: 21.5 | H16: 15.5 | I16: 19 | J16: 2 | K16: 17 | L16: 16.5 | M16: 2 | N16: 14 | O16: 19 | P16: 2 | Q16: 2 | R16: =SUM(H16:O16) -> 105 | S16: 6 | T16: =R16/S16 -> 17.5 | U16: =T16*2 -> 35 | V16: 14 | W16: 21.5 | X16: 2 | Y16: 15.5 | Z16: 18 | AA16: 27.3 | AB16: 18 | AC16: 7.5 | AD16: 2 | AE16: =SUM(V16:AC16) -> 123.8 | AF16: 7 | AG16: =AE16/AF16 -> 17.685714 | AH16: =AG16*2 -> 35.371429 | AI16: 2 | AJ16: =F16+G16+H16+I16+K16+L16+N16+O16+V16+W16+Y16+Z16+AA16+AB16+AC16 -> 261.3 | AK16: 15 | AL16: =AJ16/AK16 -> 17.42 | AM16: =AL16*2 -> 34.84 | AN16: 20 | AO16: 14 | AP16: 17.5 | AQ16: 11.5 | AR16: 16.5 | AS16: 9 | AT16: 2 | AU16: =SUM(AN16:AS16) -> 88.5 | AV16: 6 | AW16: =AU16/AV16 -> 14.75 | AX16: =AW16*2 -> 29.5 | AY16: 17 | AZ16: 12 | BA16: 11 | BB16: 9 | BC16: 11 | BD16: 10.5 | BE16: 2 | BF16: =SUM(AY16:BD16) -> 70.5 | BG16: 6 | BH16: =BF16/BG16 -> 11.75 | BI16: =BH16*2 -> 23.5 | BJ16: =IF(OR($D16="",$AW16="",$BH16=""),"",IFERROR(IF(VALUE($BH16)>VALUE($AW16),"▲ "&TEXT(VALUE($BH16)-VALUE($AW16),"0.00"),IF(VALUE($BH16)<VALUE($AW16),"▼ "&TEXT(VALUE($AW16)-VALUE($BH16),"0.00"),"● 0.00")),"")) -> ▼ 3.00 | BK16: =SUM(AN16:AQ16)/4 -> 15.75 | BL16: =IF(OR(BK16="",BH16="",NOT(ISNUMBER(BK16)),NOT(ISNUMBER(BH16))),"",IF(BH16>BK16,"▲ "&TEXT(ABS(BH16-BK16),"0.00"),IF(BH16<BK16,"▼ "&TEXT(ABS(BH16-BK16),"0.00"),"● 0.00"))) -> ▼ 4.00 | BM16: 11 | BT16: 2 | BU16: =SUM(BM16:BS16) -> 11 | BV16: 1 | BW16: =BU16/BV16 -> 11 | BX16: =BW16*2 -> 22
